Workbook
Name category: 'CALCULATIONS AND PIVOT'!$M$19
Name city: 'CALCULATIONS AND PIVOT'!$G$19
Name copier: 'CALCULATIONS AND PIVOT'!$M$18
Name marginyoy: 'CALCULATIONS AND PIVOT'!$N$10
Name mode: 'CALCULATIONS AND PIVOT'!$G$49
Name orderyoy: 'CALCULATIONS AND PIVOT'!$N$9
Name profityoy: 'CALCULATIONS AND PIVOT'!$N$8
Name quantityyoy: 'CALCULATIONS AND PIVOT'!$N$7
Name salestrend: 'CALCULATIONS AND PIVOT'!$B$20
Name salesyoy: 'CALCULATIONS AND PIVOT'!$N$6
Name shippingduration: 'CALCULATIONS AND PIVOT'!$G$31
Name Slicer_Region: #N/A
Name Slicer_Segment: #N/A
Name Slicer_Year: #N/A
Name totalorders: 'CALCULATIONS AND PIVOT'!$J$9
Name totalprofit: 'CALCULATIONS AND PIVOT'!$J$8
Name totalprofitmargin: 'CALCULATIONS AND PIVOT'!$J$10
Name totalquantity: 'CALCULATIONS AND PIVOT'!$J$7
Name totalsales: 'CALCULATIONS AND PIVOT'!$J$6

Sheet Sample - Superstore
A1: Order ID | B1: Order Date | C1: Ship Date | D1: Ship Mode | E1: Customer ID | F1: Customer Name | G1: Segment | H1: Country | I1: City | J1: State | K1: Region | L1: Product ID | M1: Category | N1: Sub-Category | O1: Product Name | P1: Sales | Q1: Quantity | R1: Profit | S1: Duration | T1: Year | U1: Month | V1: Profit Margin
A2: CA-2014-115812 | B2: 41799 | C2: 41804 | D2: Standard Class | E2: BH-11710 | F2: Brosina Hoffman | G2: Consumer | H2: United States | I2: Los Angeles | J2: California | K2: West | L2: TEC-PH-10002275 | M2: Technology | N2: Phones | O2: Mitel 5320 IP Phone VoIP phone | P2: 907.152 | Q2: 6 | R2: 90.7152 | S2: 5 days | T2: 2014 | U2: Jun | V2: 0.1
A3: CA-2014-115812 | B3: 41799 | C3: 41804 | D3: Standard Class | E3: BH-11710 | F3: Brosina Hoffman | G3: Consumer | H3: United States | I3: Los Angeles | J3: California | K3: West | L3: TEC-PH-10002033 | M3: Technology | N3: Phones | O3: Konftel 250 Conference phone - Charcoal black | P3: 911.424 | Q3: 4 | R3: 68.3568 | S3: 5 days | T3: 2014 | U3: Jun | V3: 0.075
A4: CA-2014-143336 | B4: 41878 | C4: 41883 | D4: Second Class | E4: ZD-21925 | F4: Zuschuss Donatelli | G4: Consumer | H4: United States | I4: San Francisco | J4: California | K4: West | L4: TEC-PH-10001949 | M4: Technology | N4: Phones | O4: Cisco SPA 501G IP Phone | P4: 213.48 | Q4: 3 | R4: 16.011 | S4: 5 days | T4: 2014 | U4: Aug | V4: 0.075
A5: CA-2016-121755 | B5: 42385 | C5: 42389 | D5: Second Class | E5: EH-13945 | F5: Eric Hoffmann | G5: Consumer | H5: United States | I5: Los Angeles | J5: California | K5: West | L5: TEC-AC-10003027 | M5: Technology | N5: Accessories | O5: Imation 8GB Mini TravelDrive USB 2.0 Flash Drive | P5: 90.57 | Q5: 3 | R5: 11.7741 | S5: 4 days | T5: 2016 | U5: Jan | V5: 0.13
A6: CA-2016-117590 | B6: 42712 | C6: 42714 | D6: First Class | E6: GH-14485 | F6: Gene Hale | G6: Corporate | H6: United States | I6: Richardson | J6: Texas | K6: Central | L6: TEC-PH-10004977 | M6: Technology | N6: Phones | O6: GE 30524EE4 | P6: 1097.544 | Q6: 7 | R6: 123.4737 | S6: 2 days | T6: 2016 | U6: Dec | V6: 0.1125
A7: CA-2015-117415 | B7: 42365 | C7: 42369 | D7: Standard Class | E7: SN-20710 | F7: Steve Nguyen | G7: Home Office | H7: United States | I7: Houston | J7: Texas | K7: Central | L7: TEC-PH-10000486 | M7: Technology | N7: Phones | O7: Plantronics HL10 Handset Lifter | P7: 371.168 | Q7: 4 | R7: 41.7564 | S7: 4 days | T7: 2015 | U7: Dec | V7: 0.1125
A8: CA-2017-120999 | B8: 42988 | C8: 42993 | D8: Standard Class | E8: LC-16930 | F8: Linda Cazamias | G8: Corporate | H8: United States | I8: Naperville | J8: Illinois | K8: Central | L8: TEC-PH-10004093 | M8: Technology | N8: Phones | O8: Panasonic Kx-TS550 | P8: 147.168 | Q8: 4 | R8: 16.5564 | S8: 5 days | T8: 2017 | U8: Sep | V8: 0.1125
A9: CA-2016-118255 | B9: 42440 | C9: 42442 | D9: First Class | E9: ON-18715 | F9: Odella Nelson | G9: Corporate | H9: United States | I9: Eagan | J9: Minnesota | K9: Central | L9: TEC-AC-10000171 | M9: Technology | N9: Accessories | O9: Verbatim 25 GB 6x Blu-ray Single Layer Recordable Disc, 25/Pack | P9: 45.98 | Q9: 2 | R9: 19.7714 | S9: 2 days | T9: 2016 | U9: Mar | V9: 0.43
A10: CA-2016-169194 | B10: 42541 | C10: 42546 | D10: Standard Class | E10: LH-16900 | F10: Lena Hernandez | G10: Consumer | H10: United States | I10: Dover | J10: Delaware | K10: East | L10: TEC-AC-10002167 | M10: Technology | N10: Accessories | O10: Imation 8gb Micro Traveldrive Usb 2.0 Flash Drive | P10: 45 | Q10: 3 | R10: 4.95 | S10: 5 days | T10: 2016 | U10: Jun | V10: 0.11
A11: CA-2016-169194 | B11: 42541 | C11: 42546 | D11: Standard Class | E11: LH-16900 | F11: Lena Hernandez | G11: Consumer | H11: United States | I11: Dover | J11: Delaware | K11: East | L11: TEC-PH-10003988 | M11: Technology | N11: Phones | O11: LF Elite 3D Dazzle Designer Hard Case Cover, Lf Stylus Pen and Wiper For Apple Iphone 5c Mini Lite | P11: 21.8 | Q11: 2 | R11: 6.104 | S11: 5 days | T11: 2016 | U11: Jun | V11: 0.28
A12: CA-2016-105816 | B12: 42715 | C12: 42721 | D12: Standard Class | E12: JM-15265 | F12: Janet Molinari | G12: Corporate | H12: United States | I12: New York City | J12: New York | K12: East | L12: TEC-PH-10002447 | M12: Technology | N12: Phones | O12: AT&T CL83451 4-Handset Telephone | P12: 1029.95 | Q12: 5 | R12: 298.6855 | S12: 6 days | T12: 2016 | U12: Dec | V12: 0.29
A13: CA-2016-111682 | B13: 42538 | C13: 42539 | D13: First Class | E13: TB-21055 | F13: Ted Butterfield | G13: Consumer | H13: United States | I13: Troy | J13: New York | K13: East | L13: TEC-AC-10002167 | M13: Technology | N13: Accessories | O13: Imation 8gb Micro Traveldrive Usb 2.0 Flash Drive | P13: 30 | Q13: 2 | R13: 3.3 | S13: 1 days | T13: 2016 | U13: Jun | V13: 0.11
... A1848: CA-2017-121258 | B1848: 42792 | C1848: 42797 | D1848: Standard Class | E1848: DB-13060 | F1848: Dave Brooks | G1848: Consumer | H1848: United States | I1848: Costa Mesa | J1848: California | K1848: West | L1848: TEC-PH-10003645 | M1848: Technology | N1848: Phones | O1848: Aastra 57i VoIP phone | P1848: 258.576 | Q1848: 2 | R1848: 19.3932 | S1848: 5 days | T1848: 2017 | U1848: Feb | V1848: 0.075

Sheet CALCULATIONS AND PIVOT
B4: Sum of Sales | C4: Sum of Quantity | D4: Sum of Profit | E4: Count of Order ID | F4: Average of Profit Margin | I4: Key Performance Indicators
B5: 836154.03 | C5: 6939 | D5: 145454.95 | E5: 1847 | F5: 0.15613805 | I5: TOTAL VALUES | J5: Totals | K5: Current year | L5: Previous year | M5: YOY%
I6: SALES | J6: =GETPIVOTDATA("Sum of Sales",$B$4) -> 836154.03 | K6: =GETPIVOTDATA("Sum of Sales",$B$11,"Year",2017) -> 271730.81 | L6: =GETPIVOTDATA("Sum of Sales",$B$11,"Year",2016) -> 226364.18 | M6: =('CALCULATIONS AND PIVOT'!K6-'CALCULATIONS AND PIVOT'!L6)/'CALCULATIONS AND PIVOT'!L6 -> 0.20041435 | N6: =IF(M6>0,"▲","▼")&TEXT(ABS(M6),"0.0%")&" YoY" -> ▲20.0% YoY
I7: QUANTITY | J7: =GETPIVOTDATA("Sum of Quantity",$B$4) -> 6939 | K7: =GETPIVOTDATA("Sum of Quantity",$B$11,"Year",2017) -> 2363 | L7: =GETPIVOTDATA("Sum of Quantity",$B$11,"Year",2016) -> 1698 | M7: =('CALCULATIONS AND PIVOT'!K7-'CALCULATIONS AND PIVOT'!L7)/'CALCULATIONS AND PIVOT'!L7 -> 0.39163722 | N7: =IF(M7>0,"▲","▼")&TEXT(ABS(M7),"0.0%")&" YoY" -> ▲39.2% YoY
I8: PROFIT | J8: =GETPIVOTDATA("Sum of Profit",$B$4) -> 145454.95 | K8: =GETPIVOTDATA("Sum of Profit",$B$11,"Year",2017) -> 50684.257 | L8: =GETPIVOTDATA("Sum of Profit",$B$11,"Year",2016) -> 39773.992 | M8: =('CALCULATIONS AND PIVOT'!K8-'CALCULATIONS AND PIVOT'!L8)/'CALCULATIONS AND PIVOT'!L8 -> 0.2743065 | N8: =IF(M8>0,"▲","▼")&TEXT(ABS(M8),"0.0%")&" YoY" -> ▲27.4% YoY
I9: ORDERS | J9: =GETPIVOTDATA("Count of Order ID",$B$4) -> 1847 | K9: =GETPIVOTDATA("Count of Order ID",$B$11,"Year",2017) -> 624 | L9: =GETPIVOTDATA("Count of Order ID",$B$11,"Year",2016) -> 459 | M9: =('CALCULATIONS AND PIVOT'!K9-'CALCULATIONS AND PIVOT'!L9)/'CALCULATIONS AND PIVOT'!L9 -> 0.35947712 | N9: =IF(M9>0,"▲","▼")&TEXT(ABS(M9),"0.0%")&" YoY" -> ▲35.9% YoY
I10: PROFIT MARGIN | J10: =J8/J6 -> 0.17395712 | K10: =K8/K6 -> 0.18652377 | L10: =L8/L6 -> 0.17570798 | M10: =('CALCULATIONS AND PIVOT'!K10-'CALCULATIONS AND PIVOT'!L10)/'CALCULATIONS AND PIVOT'!L10 -> 0.061555534 | N10: =IF(M10>0,"▲","▼")&TEXT(ABS(M10),"0.0%")&" YoY" -> ▲6.2% YoY
B11: Row Labels | C11: Sum of Sales | D11: Sum of Quantity | E11: Sum of Profit | F11: Count of Order ID | G11: Average of Profit Margin
B12: 2014 | C12: 175278.23 | D12: 1389 | E12: 21492.833 | F12: 355 | G12: 0.16060731
B13: 2015 | C13: 162780.81 | D13: 1489 | E13: 33503.867 | F13: 409 | G13: 0.16766358
B14: 2016 | C14: 226364.18 | D14: 1698 | E14: 39773.992 | F14: 459 | G14: 0.13429609
B15: 2017 | C15: 271730.81 | D15: 2363 | E15: 50684.257 | F15: 624 | G15: 0.1621075
B16: Grand Total | C16: 836154.03 | D16: 6939 | E16: 145454.95 | F16: 1847 | G16: 0.15613805
G18: SALES BY CITY | M18: ="Highest Profit Category: "& INDEX(M21:M24,MATCH(MAX(O21:O24),O21:O24,0)) & " (" &TEXT(MAX(O21:O24),"$#,##0") &")" -> Highest Profit Category: Copiers ($55,618)
B19: MONTHLY SALES TREND | G19: ="Top Selling City: "&INDEX(G21:G25,MATCH(MAX(H21:H25),H21:H25,0)) &" (" &TEXT(MAX(H21:H25),"$#,##0") &")" -> Top Selling City: New York City ($109,316) | M19: ="Highest Sales from category: "& INDEX(M21:M24,MATCH(MAX(N21:N24),N21:N24,0)) &" (" &TEXT(MAX(N21:N24),"$#,##0") &")" -> Highest Sales from category: Phones ($330,007)
B20: ="Peak Sales Month: " &INDEX(B22:B33,MATCH(MAX(C22:C33),C22:C33,0)) &" with"&TEXT(MAX(C22:C33)," $#,##0")&" in Sales" -> Peak Sales Month: Nov with $131,135 in Sales | G20: Row Labels | H20: Sum of Sales | K20: =MAX(J21:J25)*1.2 -> 131179.33 | M20: Row Labels | N20: Sum of Sales | O20: Sum of Profit
B21: Row Labels | C21: Sum of Sales | G21: Los Angeles | H21: 73029.786 | I21: Los Angeles | J21: 73029.786 | K21: =$K$20-J21 -> 58149.541 | M21: Copiers | N21: 149528.03 | O21: 55617.825
B22: Jan | C22: 30121.763 | G22: New York City | H22: 109316.11 | I22: New York City | J22: 109316.11 | K22: =$K$20-J22 -> 21863.221 | M22: Accessories | N22: 167380.32 | O22: 41936.636
B23: Feb | C23: 23343.418 | G23: Philadelphia | H23: 41923.319 | I23: Philadelphia | J23: 41923.319 | K23: =$K$20-J23 -> 89256.008 | M23: Machines | N23: 189238.63 | O23: 3384.7569
B24: Mar | C24: 97851.57 | G24: San Francisco | H24: 34058.632 | I24: San Francisco | J24: 34058.632 | K24: =$K$20-J24 -> 97120.695 | M24: Phones | N24: 330007.05 | O24: 44515.731
B25: Apr | C25: 47630.275 | G25: Seattle | H25: 42506.372 | I25: Seattle | J25: 42506.372 | K25: =$K$20-J25 -> 88672.955 | M25: Grand Total | N25: 836154.03 | O25: 145454.95
B26: May | C26: 63642.155 | G26: Grand Total | H26: 300834.22
B27: Jun | C27: 48304.583
B28: Jul | C28: 54854.026 | X28: P
B29: Aug | C29: 52025.856
B30: Sep | C30: 99380.709 | G30: ORDERS BY SHIPPING DURATION
B31: Oct | C31: 87031.945 | G31: ="Most Orders ("&TEXT(MAX(H33:H40),"0%")&") were delivered in "&INDEX(G33:G40,MATCH(MAX(H33:H40),H33:H40,0)) -> Most Orders (28%) were delivered in 4 days
B32: Nov | C32: 131134.84 | G32: Row Labels | H32: Count of Order ID
B33: Dec | C33: 100832.89 | G33: 4 days | H33: 0.2777477
B34: Grand Total | C34: 836154.03 | G34: 5 days | H34: 0.21277748
G35: 2 days | H35: 0.1402274
G36: 6 days | H36: 0.11802924
G37: 3 days | H37: 0.10395236
B38: Row Labels | C38: Sum of Sales | D38: STATE | E38: SALES | G38: 7 days | H38: 0.0584732
B39: Alabama | C39: 8969.08 | D39: Alabama | E39: 8969.08 | G39: 0 days | H39: 0.050351922
B40: Arizona | C40: 11750.885 | D40: Arizona | E40: 11750.885 | G40: 1 days | H40: 0.038440715
B41: Arkansas | C41: 3925.25 | D41: Arkansas | E41: 3925.25 | G41: Grand Total | H41: 1
B42: California | C42: 159271.08 | D42: California | E42: 159271.08
B43: Colorado | C43: 10966.329 | D43: Colorado | E43: 10966.329
B44: Connecticut | C44: 2791.03 | D44: Connecticut | E44: 2791.03
...

Sheet WIREFRAME

Sheet DASHBOARD
BR32: s

Sheet Sheet1
